Workbook
Name itensorc_desconto: #REF!
Name itensorc_descricao: #REF!
Name itensorc_encargos: #REF!
Name itensorc_especifica: #REF!
Name itensorc_item: #REF!
Name itensorc_lancamento: #REF!
Name itensorc_percentualhonorarios: #REF!
Name itensorc_quantidade: #REF!
Name itensorc_situacao: #REF!
Name itensorc_subtipo: #REF!
Name itensorc_tiporeceita: #REF!
Name itensorc_valor: #REF!
Name itensorc_valorfornecedor: #REF!
Name itensorc_valorfornecedorunitario: #REF!
Name itensorc_valorunitario: #REF!

Sheet RESUMO
C3: 45866 | E3: =SUM(#REF!) -> #REF!
C4: 45867
C5: VÍDEO
C6: STUDIO ROCA
C7: TOTAL
B12: CÓDIGO DO JOB: | C12: Mot_007
B13: CLIENTE: | C13: MOTOROLA
B14: EVENTO: | C14: São Paulo Innovation Week 2026
B15: LOCAL: | C15: Arena Mercado Livre
B16: DATA: | C16: 13,14 e 15/Maio
B17: ATENDIMENTO: | C17: Fernanda Pinheiro
B18: PRODUTOR: | C18: Silvia Brito
B19: NOME PLANILHA: | C19: Mot_007_São Paulo Innovation Week 2026
C21: VENDA | D21: CUSTO | E21: LUCRO
B22: PRINCIPAL | C22: ='OPÇÃO 1'!N51 -> 151344.18 | D22: ='OPÇÃO 1'!X51 -> 109742.67 | E22: =C22-D22 -> 41601.513 | F22: =E22*100%/C22 -> 0.27488016
B23: EXTRAS | C23: =EXTRAS!N21 -> 5541.0563 | D23: =EXTRAS!X21 -> 2130 | E23: =C23-D23 -> 3411.0563 | F23: =E23*100%/C23 -> 0.61559676
B24: TOTAL | C24: =SUM(C22:C22) -> 151344.18 | D24: =SUM(D22:D23) -> 111872.67 | E24: =SUM(E22:E23) -> 45012.57 | F24: =E24*100%/C24 -> 0.29741856
B29: NOTAS EMITIDAS
B30: NOTA DE DÉBITO 08 | C30: 129941.3 | D30: =SUM(D24) -> 111872.67 | E30: =(C30+C31)-D30 -> 45012.57 | F30: =E30*100%/C32 -> 0.28691399
B31: NOTA DE DÉBITO 09 | C31: 26943.94
C32: =SUM(C30:C31) -> 156885.24 | D32: =SUM(D30:D30) -> 111872.67 | E32: =C32-D32 -> 45012.57 | F32: =E32*100%/C32 -> 0.28691399

Sheet OPÇÃO 1
F1: ORÇAMENTO 5.2
F2: Oggi Comunicação e Eventos
F4: CÓDIGO DO JOB: | G4: Mot_007
F5: CLIENTE: | G5: MOTOROLA
F6: EVENTO: | G6: São Paulo Innovation Week 2026
F7: LOCAL: | G7: Arena Mercado Livre
F8: DATA: | G8: 13,14 e 15/Maio
F9: ATENDIMENTO: | G9: Fernanda Pinheiro
F10: PRODUTOR: | G10: Silvia Brito
F11: NOME PLANILHA: | G11: Mot_007_São Paulo Innovation Week 2026
Q12: CUSTOS (valor de custo c/ NF ou recibo) | U12: DIFERENÇA NF (Lucro) | Y12: ENCARGOS PUBLI | Z12: =(1/(1-M14))-1 -> 0.24269914 | AC12: SOLICITAÇÃO DE PAGAMENTO | AG12: FORNECEDOR | AJ12: Solicitado | AK12: PAGAMENTOS
A13: ÍNDICE | B13: ÍNDICE PUBLI | C13: CATEGORIA | D13: TIPO DE CUSTOS | E13: TIPO DE FATURAMENTO | M13: 0.8047
A14: 0 | F14: RESUMO | G14: DESCRITIVO | H14: Qtd | I14: Diária | J14: R$ unit | K14: VALOR | L14: 0.08 | M14: =1-M13 -> 0.1953 | N14: SUBTOTAL | Q14: QTDE | R14: DIÁRIA | S14: VL. UNIT. | T14: SUB TOTAL | U14: DIFERENÇA | V14: % NOTA | W14: CUSTO NOTA | X14: CUSTO TOTAL (custo + dif. NF) | Y14: CUSTO TOTAL + IMPOSTOS | Z14: Margem | AA14: Peso | AC14: Valor Total | AD14: Saldo | AE14: Data | AG14: Fornecedor | AH14: CPF/CNPJ | AK14: PENDENTE | AL14: EFETUADO | AM14: PENDENTE | AN14: EFETUADO
A15: 1 | B15: 1 | C15: GRUPO | F15: INTERNO OGGI | Q15: =IF(F15<>"",F15,"") -> INTERNO OGGI
A16: 2 | B16: 1.1 | C16: SUBGRUPO | F16: INTERNOS | L16: AGENCIAMENTO | M16: IMPOSTOS | N16: SUBTOTAL | Q16: =IF(F16<>"",F16,"") -> INTERNOS | Z16: Marg. | AA16: Peso
A17: 3 | B17: 1.1.1 | C17: ITEM | D17: INTERNO | E17: FAT.OGGI | F17: CRIAÇÃO | G17: NOVO PROJETO. | H17: 1 | I17: 1 | J17: 3400 | K17: =IF(F17<>"",H17*I17*J17,"") -> 3400 | L17: =IF(K17<>"",IF(D17="INTERNO",0,K17*$L$14),"") -> 0 | M17: =IF(K17<>"",IF(E17="FAT.OGGI",SUM(K17:L17)*(1/(1-$M$14)-1),L17*(1/(1-$M$14)-1)),"") -> 825.17708 | N17: =SUM(K17:M17) -> 4225.1771 | Q17: =IF(H17<>"",H17,"") -> 1 | R17: =IF(I17<>"",I17,"") -> 1 | S17: 700 | T17: =IF(Q17<>"",Q17*R17*S17,"") -> 700 | U17: =IF(Q17<>"",K17-T17,"") -> 2700 | V17: =IF(Q17<>"",0%,"") -> 0 | W17: =IF(Q17<>"",V17*U17,"") -> 0 | X17: =IF(Q17<>"",W17+T17,"") -> 700 | Y17: =IF(Q17<>"",X17+M17,"") -> 1525.1771 | Z17: =IF(Q17<>"",U17/K17,"") -> 0.79411765 | AA17: =T17/$T$21 -> 1 | AM17: =X17-AN17 -> 0 | AN17: 700 | AO17: STARTA
A18: 4 | B18: 1.1.2 | C18: ITEM | D18: INTERNO | E18: FAT.OGGI | F18: PLANEJAMENTO | G18: PLANEJAMENTO DO PROJETO Planejamento de dinâmicas e cronograma do evento. | H18: 1 | I18: 0 | J18: 2000 | K18: =IF(F18<>"",H18*I18*J18,"") -> 0 | L18: =IF(K18<>"",IF(D18="INTERNO",0,K18*$L$14),"") -> 0 | M18: =IF(K18<>"",IF(E18="FAT.OGGI",SUM(K18:L18)*(1/(1-$M$14)-1),L18*(1/(1-$M$14)-1)),"") -> 0 | N18: =SUM(K18:M18) -> 0 | Q18: =IF(H18<>"",H18,"") -> 1 | R18: =IF(I18<>"",I18,"") -> 0 | S18: 1000 | T18: =IF(Q18<>"",Q18*R18*S18,"") -> 0 | U18: =IF(Q18<>"",K18-T18,"") -> 0 | V18: =IF(Q18<>"",0%,"") -> 0 | W18: =IF(Q18<>"",V18*U18,"") -> 0 | X18: =IF(Q18<>"",W18+T18,"") -> 0 | Y18: =IF(Q18<>"",X18+M18,"") -> 0 | Z18: =IF(Q18<>"",U18/K18,"") -> #DIV/0! | AA18: =T18/$T$21 -> 0 | AM18: =X18-AN18 -> 0
A19: 5 | B19: 1.1.3 | C19: ITEM | D19: INTERNO | E19: FAT.OGGI | F19: ATENDIMENTO | G19: ATENDIMENTO EXCLUSIVO 01 profissional de atendimento por 01 mes Pré-evento, evento e entrega de relatório | H19: 1 | I19: 1 | J19: 5000 | K19: =IF(F19<>"",H19*I19*J19,"") -> 5000 | L19: =IF(K19<>"",IF(D19="INTERNO",0,K19*$L$14),"") -> 0 | M19: =IF(K19<>"",IF(E19="FAT.OGGI",SUM(K19:L19)*(1/(1-$M$14)-1),L19*(1/(1-$M$14)-1)),"") -> 1213.4957 | N19: =SUM(K19:M19) -> 6213.4957 | Q19: =IF(H19<>"",H19,"") -> 1 | R19: =IF(I19<>"",I19,"") -> 1 | S19: 800 | T19: 0 | U19: =IF(Q19<>"",K19-T19,"") -> 5000 | V19: =IF(Q19<>"",0%,"") -> 0 | W19: =IF(Q19<>"",V19*U19,"") -> 0 | X19: =IF(Q19<>"",W19+T19,"") -> 0 | Y19: =IF(Q19<>"",X19+M19,"") -> 1213.4957 | Z19: =IF(Q19<>"",U19/K19,"") -> 1 | AA19: =T19/$T$21 -> 0 | AM19: =X19-AN19 -> 0
A20: 6 | B20: 1.1.4 | C20: ITEM | D20: INTERNO | E20: FAT.OGGI | F20: PRODUÇÃO | G20: PRODUTOR EXECUTIVO 01 profissional de atendimento/produção. Pré-evento, evento e entrega de relatório | H20: 1 | I20: 1 | J20: 4500 | K20: =IF(F20<>"",H20*I20*J20,"") -> 4500 | L20: =IF(K20<>"",IF(D20="INTERNO",0,K20*$L$14),"") -> 0 | M20: =IF(K20<>"",IF(E20="FAT.OGGI",SUM(K20:L20)*(1/(1-$M$14)-1),L20*(1/(1-$M$14)-1)),"") -> 1092.1461 | N20: =SUM(K20:M20) -> 5592.1461 | Q20: =IF(H20<>"",H20,"") -> 1 | R20: =IF(I20<>"",I20,"") -> 1 | S20: 800 | T20: 0 | U20: =IF(Q20<>"",K20-T20,"") -> 4500 | V20: =IF(Q20<>"",0%,"") -> 0 | W20: =IF(Q20<>"",V20*U20,"") -> 0 | X20: =IF(Q20<>"",W20+T20,"") -> 0 | Y20: =IF(Q20<>"",X20+M20,"") -> 1092.1461 | Z20: =IF(Q20<>"",U20/K20,"") -> 1 | AA20: =T20/$T$21 -> 0 | AM20: =X20-AN20 -> 0
A21: 7 | C21: SUBTOTAL GRUPO | F21: Subtotal INTERNO OGGI | K21: =SUM(K17:K20) -> 12900 | L21: =SUM(L17:L20) -> 0 | M21: =SUM(M17:M20) -> 3130.8189 | N21: =SUM(N17:N20) -> 16030.819 | Q21: Subtotal INTERNO OGGI | T21: =SUM(T17:T20) -> 700 | U21: =SUM(U17:U20) -> 12200 | X21: =SUM(X17:X20) -> 700 | Y21: =IF(Q21<>"",X21+M21,"") -> 3830.8189
A22: 8 | B22: 2 | C22: GRUPO | F22: CENOGRAFIA | Q22: =IF(F22<>"",F22,"") -> CENOGRAFIA
A23: 9 | B23: 2.1 | C23: SUBGRUPO | F23: ESTANDE | L23: AGENCIAMENTO | M23: IMPOSTOS | N23: SUBTOTAL | Q23: =IF(F23<>"",F23,"") -> ESTANDE | Z23: Marg. | AA23: Peso
A24: 10 | B24: 2.1.1 | C24: ITEM | D24: OPERACIONAL | E24: FAT.CLIENTE | F24: ESTANDE | G24: trANSPORTE DE MATERIAIS Reserva de verba para transporte de materiais (Mesa Motorola) | H24: 1 | I24: 1 | J24: 81000 | K24: =IF(F24<>"",H24*I24*J24,"") -> 81000 | L24: =IF(K24<>"",IF(D24="INTERNO",0,K24*$L$14),"") -> 6480 | M24: =IF(K24<>"",IF(E24="FAT.OGGI",SUM(K24:L24)*(1/(1-$M$14)-1),L24*(1/(1-$M$14)-1)),0) -> 1572.6904 | N24: =SUM(K24:M24) -> 89052.69 | Q24: =IF(H24<>"",H24,"") -> 1 | R24: =IF(I24<>"",I24,"") -> 1 | S24: 72000 | T24: =IF(Q24<>"",Q24*R24*S24,"") -> 72000 | U24: =IF(Q24<>"",K24-T24,"") -> 9000 | V24: =IF(Q24<>"",0%,"") -> 0 | W24: =IF(Q24<>"",V24*U24,"") -> 0 | X24: =IF(Q24<>"",W24+T24,"") -> 72000 | Y24: =IF(Q24<>"",X24+M24,"") -> 73572.69 | Z24: =IF(Q24<>"", IFERROR(U24/K24, 0), 0) -> 0.11111111 | AA24: =IFERROR(T24/$T$25, "") -> 1 | AM24: =X24-AN24 -> 0 | AN24: =36000+36000 -> 72000 | AO24: MILENA DI PAULA
A25: 11 | C25: SUBTOTAL SUBGRUPO | F25: Subtotal ESTANDE | K25: =SUM(K24:K24) -> 81000 | L25: =SUM(L24:L24) -> 6480 | M25: =SUM(M24:M24) -> 1572.6904 | N25: =SUM(N24:N24) -> 89052.69 | Q25: Subtotal ESTANDE | T25: =SUM(T24:T24) -> 72000 | U25: =SUM(U24:U24) -> 9000 | X25: =SUM(X24:X24) -> 72000 | Y25: =IF(Q25<>"",X25+M25,"") -> 73572.69
A26: 12 | B26: 2.2 | C26: SUBGRUPO | F26: TECNICA | L26: AGENCIAMENTO | M26: IMPOSTOS | N26: SUBTOTAL | Q26: =IF(F26<>"",F26,"") -> TECNICA | Z26: Marg. | AA26: Peso
A27: 13 | B27: 2.2.1 | C27: ITEM | D27: OPERACIONAL | E27: FAT.CLIENTE | F27: PAINEL DE LED | G27: Painel de led P3 outdoor 3x2m.Frete, montagem e desmontagem e tecnico para manutenção diária. | H27: 1 | I27: 1 | J27: 7550 | K27: =IF(F27<>"",H27*I27*J27,"") -> 7550 | L27: =IF(K27<>"",IF(D27="INTERNO",0,K27*$L$14),"") -> 604 | M27: =IF(K27<>"",IF(E27="FAT.OGGI",SUM(K27:L27)*(1/(1-$M$14)-1),L27*(1/(1-$M$14)-1)),0) -> 146.59028 | N27: =SUM(K27:M27) -> 8300.5903 | Q27: =IF(H27<>"",H27,"") -> 1 | R27: =IF(I27<>"",I27,"") -> 1 | S27: 5800 | T27: 9300 | U27: =IF(Q27<>"",K27-T27,"") -> -1750 | V27: =IF(Q27<>"",0%,"") -> 0 | W27: =IF(Q27<>"",V27*U27,"") -> 0 | X27: =IF(Q27<>"",W27+T27,"") -> 9300 | Y27: =IF(Q27<>"",X27+M27,"") -> 9446.5903 | Z27: =IF(Q27<>"", IFERROR(U27/K27, 0), 0) -> -0.23178808 | AA27: =IFERROR(T27/$T$28, "") -> 1 | AM27: =X27-AN27 -> 0 | AN27: =3500+5800 -> 9300 | AO27: MW LED - MILENA DI PAULA
A28: 16 | C28: SUBTOTAL SUBGRUPO | F28: Subtotal TECNICA | K28: =SUM(K27:K27) -> 7550 | L28: =SUM(L27:L27) -> 604 | M28: =SUM(M27:M27) -> 146.59028 | N28: =SUM(N27:N27) -> 8300.5903 | Q28: Subtotal TECNICA | T28: =SUM(T27:T27) -> 9300 | U28: =SUM(U27:U27) -> -1750 | X28: =SUM(X27:X27) -> 9300 | Y28: =IF(Q28<>"",X28+M28,"") -> 9446.5903
A29: 17 | B29: 3 | C29: GRUPO | F29: OPERACIONAL ESTANDE | Q29: =IF(F29<>"",F29,"") -> OPERACIONAL ESTANDE
A30: 18 | B30: 3.1 | C30: SUBGRUPO | F30: STAFF | L30: AGENCIAMENTO | M30: IMPOSTOS | N30: SUBTOTAL | Q30: =IF(F30<>"",F30,"") -> STAFF | Z30: Marg. | AA30: Peso
A31: 19 | B31: 3.1.1 | C31: ITEM | D31: OPERACIONAL | E31: FAT.CLIENTE | F31: PRODUTOR MONTAGEM / DESMONTAGEM / SERVIÇOS | G31: PRODUTOR - MONTAGEM E DESMONTAGEM 01 - Produtor de Montagem e desmontagem.3 dias de Montagem + 01 dia de desmontagem. | H31: 1 | I31: 4 | J31: 850 | K31: =IF(F31<>"",H31*I31*J31,"") -> 3400 | L31: =IF(K31<>"",IF(D31="INTERNO",0,K31*$L$14),"") -> 272 | M31: =IF(K31<>"",IF(E31="FAT.OGGI",SUM(K31:L31)*(1/(1-$M$14)-1),L31*(1/(1-$M$14)-1)),0) -> 66.014167 | N31: =SUM(K31:M31) -> 3738.0142 | Q31: =IF(H31<>"",H31,"") -> 1 | R31: =IF(I31<>"",I31,"") -> 4 | S31: 700 | T31: =IF(Q31<>"",Q31*R31*S31,"") -> 2800 | U31: =IF(Q31<>"",K31-T31,"") -> 600 | V31: =IF(Q31<>"",0%,"") -> 0 | W31: =IF(Q31<>"",V31*U31,"") -> 0 | X31: =IF(Q31<>"",W31+T31,"") -> 2800 | Y31: =IF(Q31<>"",X31+M31,"") -> 2866.0142 | Z31: =IF(Q31<>"", IFERROR(U31/K31, 0), 0) -> 0.17647059 | AA31: =IFERROR(T31/$T$35, "") -> 0.43410853 | AM31: =X31-AN31 -> 0 | AN31: 2800 | AO31: WILLIANS
A32: 20 | B32: 3.1.2 | C32: ITEM | D32: OPERACIONAL | E32: FAT.CLIENTE | F32: PRODUTOR OPERACIONAL | G32: PRODUTORES - GERAL 01 - Produtor Geral de Apoio de 12 a 15 de Maio. | H32: 1 | I32: 4 | J32: 850 | K32: =IF(F32<>"",H32*I32*J32,"") -> 3400 | L32: =IF(K32<>"",IF(D32="INTERNO",0,K32*$L$14),"") -> 272 | M32: =IF(K32<>"",IF(E32="FAT.OGGI",SUM(K32:L32)*(1/(1-$M$14)-1),L32*(1/(1-$M$14)-1)),0) -> 66.014167 | N32: =SUM(K32:M32) -> 3738.0142 | O32: RENATA | Q32: 1 | R32: 4 | S32: 650 | T32: =IF(Q32<>"",Q32*R32*S32,"") -> 2600 | U32: =IF(Q32<>"",K32-T32,"") -> 800 | V32: =IF(Q32<>"",0%,"") -> 0 | W32: =IF(Q32<>"",V32*U32,"") -> 0 | X32: =IF(Q32<>"",W32+T32,"") -> 2600 | Y32: =IF(Q32<>"",X32+M32,"") -> 2666.0142 | Z32: =IF(Q32<>"", IFERROR(U32/K32, 0), 0) -> 0.23529412 | AA32: =IFERROR(T32/$T$35, "") -> 0.40310078 | AM32: =X32-AN32 -> 0 | AN32: 2600 | AO32: THIAGO GOMES
A33: 21 | B33: 3.1.3 | C33: ITEM | D33: OPERACIONAL | E33: FAT.CLIENTE | F33: LIMPEZA OFICIAL EVENTO | G33: LIMPEZA Considerado profissionais de limpeza para montagem, evento e desmontagem.Carga horária: 12 horas | H33: 1 | I33: 4 | J33: 500 | K33: =IF(F33<>"",H33*I33*J33,"") -> 2000 | L33: =IF(K33<>"",IF(D33="INTERNO",0,K33*$L$14),"") -> 160 | M33: =IF(K33<>"",IF(E33="FAT.OGGI",SUM(K33:L33)*(1/(1-$M$14)-1),L33*(1/(1-$M$14)-1)),0) -> 38.831863 | N33: =SUM(K33:M33) -> 2198.8319 | Q33: =IF(H33<>"",H33,"") -> 1 | R33: 1 | S33: 800 | T33: =IF(Q33<>"",Q33*R33*S33,"") -> 800 | U33: =IF(Q33<>"",K33-T33,"") -> 1200 | V33: =IF(Q33<>"",0%,"") -> 0 | W33: =IF(Q33<>"",V33*U33,"") -> 0 | X33: =IF(Q33<>"",W33+T33,"") -> 800 | Y33: =IF(Q33<>"",X33+M33,"") -> 838.83186 | Z33: =IF(Q33<>"", IFERROR(U33/K33, 0), 0) -> 0.6 | AA33: =IFERROR(T33/$T$35, "") -> 0.12403101 | AM33: =X33-AN33 -> 0 | AN33: 800 | AO33: ROSICLEIDE
A34: 22 | B34: 3.1.4 | C34: ITEM | D34: OPERACIONAL | E34: FAT.CLIENTE | F34: CARREGADORES | G34: CARREGADORES Considerado carregadores para montagem e desmontagem.Carga horária: 12 horas | H34: 1 | I34: 2 | J34: 380 | K34: =IF(F34<>"",H34*I34*J34,"") -> 760 | L34: =IF(K34<>"",IF(D34="INTERNO",0,K34*$L$14),"") -> 60.8 | M34: =IF(K34<>"",IF(E34="FAT.OGGI",SUM(K34:L34)*(1/(1-$M$14)-1),L34*(1/(1-$M$14)-1)),0) -> 14.756108 | N34: =SUM(K34:M34) -> 835.55611 | Q34: 1 | R34: 1 | S34: 250 | T34: =IF(Q34<>"",Q34*R34*S34,"") -> 250 | U34: =IF(Q34<>"",K34-T34,"") -> 510 | V34: =IF(Q34<>"",0%,"") -> 0 | W34: =IF(Q34<>"",V34*U34,"") -> 0 | X34: =IF(Q34<>"",W34+T34,"") -> 250 | Y34: =IF(Q34<>"",X34+M34,"") -> 264.75611 | Z34: =IF(Q34<>"", IFERROR(U34/K34, 0), 0) -> 0.67105263 | AA34: =IFERROR(T34/$T$35, "") -> 0.03875969 | AM34: =X34-AN34 -> 0 | AN34: 250 | AO34: WAGNER CESAR
A35: 23 | C35: SUBTOTAL SUBGRUPO | F35: Subtotal STAFF | K35: =SUM(K31:K34) -> 9560 | L35: =SUM(L31:L34) -> 764.8 | M35: =SUM(M31:M34) -> 185.6163 | N35: =SUM(N31:N34) -> 10510.416 | Q35: Subtotal STAFF | T35: =SUM(T31:T34) -> 6450 | U35: =SUM(U31:U34) -> 3110 | X35: =SUM(X31:X34) -> 6450 | Y35: =IF(Q35<>"",X35+M35,"") -> 6635.6163
A36: 24 | B36: 3.2 | C36: SUBGRUPO | F36: OPERAÇÃO ESTANDE | L36: AGENCIAMENTO | M36: IMPOSTOS | N36: SUBTOTAL | Q36: =IF(F36<>"",F36,"") -> OPERAÇÃO ESTANDE | Z36: Marg. | AA36: Peso
A37: 25 | B37: 3.2.1 | C37: ITEM | D37: OPERACIONAL | E37: FAT.CLIENTE | F37: SEGURO | G37: SEGURO RC + RD + AP Contratação de Seguro | H37: 1 | I37: 1 | J37: 2500 | K37: =IF(F37<>"",H37*I37*J37,"") -> 2500 | L37: =IF(K37<>"",IF(D37="INTERNO",0,K37*$L$14),"") -> 200 | M37: =IF(K37<>"",IF(E37="FAT.OGGI",SUM(K37:L37)*(1/(1-$M$14)-1),L37*(1/(1-$M$14)-1)),0) -> 48.539829 | N37: =SUM(K37:M37) -> 2748.5398 | Q37: =IF(H37<>"",H37,"") -> 1 | R37: =IF(I37<>"",I37,"") -> 1 | S37: 1900 | T37: =IF(Q37<>"",Q37*R37*S37,"") -> 1900 | U37: =IF(Q37<>"",K37-T37,"") -> 600 | V37: =IF(Q37<>"",0%,"") -> 0 | W37: =IF(Q37<>"",V37*U37,"") -> 0 | X37: =IF(Q37<>"",W37+T37,"") -> 1900 | Y37: =IF(Q37<>"",X37+M37,"") -> 1948.5398 | Z37: =IF(Q37<>"", IFERROR(U37/K37, 0), 0) -> 0.24 | AA37: =IFERROR(T37/$T$42, "") -> 0.12293621 | AM37: =X37-AN37 -> 0 | AN37: 1900 | AO37: BERKLEY
A38: 26 | B38: 3.2.2 | C38: ITEM | D38: OPERACIONAL | E38: FAT.CLIENTE | F38: ALIMENTAÇÃO E TRANSPORTE EQUIPE INTERNA | G38: ALIMENTAÇÃO E TRANSPORTE EQUIPE INTERNA Reserva de verba para alimentação e transporte da equipe interna.Prod de montagem, de apoio e executiva. | H38: 2 | I38: 6 | J38: 250 | K38: =IF(F38<>"",H38*I38*J38,"") -> 3000 | L38: =IF(K38<>"",IF(D38="INTERNO",0,K38*$L$14),"") -> 240 | M38: =IF(K38<>"",IF(E38="FAT.OGGI",SUM(K38:L38)*(1/(1-$M$14)-1),L38*(1/(1-$M$14)-1)),0) -> 58.247794 | N38: =SUM(K38:M38) -> 3298.2478 | O38: 1000 | Q38: 2 | R38: 6 | S38: 140 | T38: 2580 | U38: =IF(Q38<>"",K38-T38,"") -> 420 | V38: =IF(Q38<>"",0%,"") -> 0 | W38: =IF(Q38<>"",V38*U38,"") -> 0 | X38: =IF(Q38<>"",W38+T38,"") -> 2580 | Y38: =IF(Q38<>"",X38+M38,"") -> 2638.2478 | Z38: =IF(Q38<>"", IFERROR(U38/K38, 0), 0) -> 0.14 | AA38: =IFERROR(T38/$T$42, "") -> 0.16693443 | AM38: =X38-AN38 -> 0 | AN38: 2580 | AO38: SILVIA BRITO
A39: 27 | B39: 3.2.3 | C39: ITEM | D39: OPERACIONAL | E39: FAT.CLIENTE | F39: TRANSPORTE DE MATERIAIS | G39: TRANSPORTE DE MATERIAIS Reserva de verba para transporte de materiais (Mesa Motorola) | H39: 1 | I39: 1 | J39: 800 | K39: =IF(F39<>"",H39*I39*J39,"") -> 800 | L39: =IF(K39<>"",IF(D39="INTERNO",0,K39*$L$14),"") -> 64 | M39: =IF(K39<>"",IF(E39="FAT.OGGI",SUM(K39:L39)*(1/(1-$M$14)-1),L39*(1/(1-$M$14)-1)),0) -> 15.532745 | N39: =SUM(K39:M39) -> 879.53275 | O39: DALVA | Q39: =IF(H39<>"",H39,"") -> 1 | R39: =IF(I39<>"",I39,"") -> 1 | S39: 550 | T39: 0 | U39: =IF(Q39<>"",K39-T39,"") -> 800 | V39: =IF(Q39<>"",0%,"") -> 0 | W39: =IF(Q39<>"",V39*U39,"") -> 0 | X39: =IF(Q39<>"",W39+T39,"") -> 0 | Y39: =IF(Q39<>"",X39+M39,"") -> 15.532745 | Z39: =IF(Q39<>"", IFERROR(U39/K39, 0), 0) -> 1 | AA39: =IFERROR(T39/$T$42, "") -> 0 | AM39: =X39-AN39 -> 0
A40: 28 | B40: 3.2.4 | C40: ITEM | D40: OPERACIONAL | E40: FAT.CLIENTE | F40: VERBA DE PRODUÇÃO | G40: VERBA DE PRODUÇÃO Reserva de verba para custos operacionais | H40: 1 | I40: 1 | J40: 1600 | K40: =IF(F40<>"",H40*I40*J40,"") -> 1600 | L40: =IF(K40<>"",IF(D41="INTERNO",0,K40*$L$14),"") -> 128 | M40: =IF(K40<>"",IF(E41="FAT.OGGI",SUM(K40:L40)*(1/(1-$M$14)-1),L40*(1/(1-$M$14)-1)),0) -> 31.06549 | N40: =SUM(K40:M40) -> 1759.0655 | Q40: =IF(H40<>"",H40,"") -> 1 | R40: =IF(I40<>"",I40,"") -> 1 | S40: =900+160.73+104.18 -> 1164.91 | T40: 3475.17 | U40: =IF(Q40<>"",K40-T40,"") -> -1875.17 | V40: =IF(Q40<>"",0%,"") -> 0 | W40: =IF(Q40<>"",V40*U40,"") -> 0 | X40: =IF(Q40<>"",W40+T40,"") -> 3475.17 | Y40: =IF(Q40<>"",X40+M40,"") -> 3506.2355 | Z40: =IF(Q40<>"", IFERROR(U40/K40, 0), 0) -> -1.1719812 | AA40: =IFERROR(T40/$T$42, "") -> 0.22485485 | AM40: =X40-AN40 -> 0 | AN40: ='CUSTOS OP.'!G15 -> 3475.17 | AO40: CUSTOS OP.
A41: 29 | B41: 3.2.5 | C41: ITEM | D41: OPERACIONAL | E41: FAT.CLIENTE | F41: CARRINHO DE CAFÉ | G41: Locação de carrinho, com cafeteira Nespresso. 100 doses/dia.Insumos e descartaveis inclusos durante os 3 dias de evento. | H41: 1 | I41: 1 | J41: 7500 | K41: =IF(F41<>"",H41*I41*J41,"") -> 7500 | L41: =IF(K41<>"",IF(D42="INTERNO",0,K41*$L$14),"") -> 600 | M41: =IF(K41<>"",IF(E42="FAT.OGGI",SUM(K41:L41)*(1/(1-$M$14)-1),L41*(1/(1-$M$14)-1)),0) -> 145.61949 | N41: =SUM(K41:M41) -> 8245.6195 | O41: vai entrar na planilha de extras o 5k | Q41: =IF(H41<>"",H41,"") -> 1 | R41: =IF(I41<>"",I41,"") -> 1 | S41: 8000 | T41: 7500 | U41: =IF(Q41<>"",K41-T41,"") -> 0 | V41: =IF(Q41<>"",0%,"") -> 0 | W41: =IF(Q41<>"",V41*U41,"") -> 0 | X41: =IF(Q41<>"",W41+T41,"") -> 7500 | Y41: =IF(Q41<>"",X41+M41,"") -> 7645.6195 | Z41: =IF(Q41<>"", IFERROR(U41/K41, 0), 0) -> 0 | AM41: =X41-AN41 -> 0 | AN41: =3500+4000 -> 7500 | AO41: MKGC EVENTOS
...

Sheet EXTRAS
F1: ORÇAMENTO 5.2
F2: Oggi Comunicação e Eventos
F4: CÓDIGO DO JOB: | G4: Mot_007
F5: CLIENTE: | G5: MOTOROLA
F6: EVENTO: | G6: São Paulo Innovation Week 2026
F7: LOCAL: | G7: Arena Mercado Livre
F8: DATA: | G8: 13,14 e 15/Maio
F9: ATENDIMENTO: | G9: Fernanda Pinheiro
F10: PRODUTOR: | G10: Silvia Brito
F11: NOME PLANILHA: | G11: Mot_007_São Paulo Innovation Week 2026
Q12: CUSTOS (valor de custo c/ NF ou recibo) | U12: DIFERENÇA NF (Lucro) | Y12: ENCARGOS PUBLI | Z12: =(1/(1-M14))-1 -> 0.24269914 | AC12: SOLICITAÇÃO DE PAGAMENTO | AG12: FORNECEDOR | AJ12: Solicitado | AK12: PAGAMENTOS
A13: ÍNDICE | B13: ÍNDICE PUBLI | C13: CATEGORIA | D13: TIPO DE CUSTOS | E13: TIPO DE FATURAMENTO | M13: 0.8047
A14: 0 | F14: RESUMO | G14: DESCRITIVO | H14: Qtd | I14: Diária | J14: R$ unit | K14: VALOR | L14: 0.08 | M14: =1-M13 -> 0.1953 | N14: SUBTOTAL | Q14: QTDE | R14: DIÁRIA | S14: VL. UNIT. | T14: SUB TOTAL | U14: DIFERENÇA | V14: % NOTA | W14: CUSTO NOTA | X14: CUSTO TOTAL (custo + dif. NF) | Y14: CUSTO TOTAL + IMPOSTOS | Z14: Margem | AA14: Peso | AC14: Valor Total | AD14: Saldo | AE14: Data | AG14: Fornecedor | AH14: CPF/CNPJ | AK14: PENDENTE | AL14: EFETUADO | AM14: PENDENTE | AN14: EFETUADO
A15: 1 | B15: 1 | C15: GRUPO | F15: EXTRAS | Q15: =IF(F15<>"",F15,"") -> EXTRAS
A16: 2 | B16: 1.1 | C16: SUBGRUPO | F16: CUSTOS EXTRAS | L16: AGENCIAMENTO | M16: IMPOSTOS | N16: SUBTOTAL | Q16: =IF(F16<>"",F16,"") -> CUSTOS EXTRAS | Z16: Marg. | AA16: Peso
A17: 3 | B17: 1.1.1 | C17: ITEM | D17: OPERACIONAL | E17: FAT.CLIENTE | F17: VIGILANTE OFICIAL EVENTO-NOTURNO | G17: SEGURANÇA Profissionais de segurança para montagem, evento e desmontagem, sendo:Carga horária: 12 horas:Das 20h30 às 08:30h.De as a 14 de Maio. | H17: 1 | I17: 4 | J17: 710 | K17: =IF(F17<>"",H17*I17*J17,"") -> 2840 | L17: =IF(K17<>"",IF(D17="INTERNO",0,K17*$L$14),"") -> 227.2 | M17: =IF(K17<>"",IF(E17="FAT.OGGI",SUM(K17:L17)*(1/(1-$M$14)-1),L17*(1/(1-$M$14)-1)),"") -> 55.141245 | N17: =SUM(K17:M17) -> 3122.3412 | Q17: =IF(H17<>"",H17,"") -> 1 | R17: 3 | S17: 710 | T17: =IF(Q17<>"",Q17*R17*S17,"") -> 2130 | U17: =IF(Q17<>"",K17-T17,"") -> 710 | V17: =IF(Q17<>"",0%,"") -> 0 | W17: =IF(Q17<>"",V17*U17,"") -> 0 | X17: =IF(Q17<>"",W17+T17,"") -> 2130 | Y17: =IF(Q17<>"",X17+M17,"") -> 2185.1412 | Z17: =IF(Q17<>"",U17/K17,"") -> 0.25 | AA17: =T17/#REF! -> #REF! | AM17: =X17-AN17 -> 0 | AN17: 2130 | AO17: SILVIA BRITO
A18: 4 | B18: 1.1.2 | C18: ITEM | D18: OPERACIONAL | E18: FAT.CLIENTE | F18: BISCOITOS PERSONALIZADOS | G18: Biscoito amanteigado 5 gramas.Personalizado.100 unidades dia . | H18: 1 | I18: 1 | J18: 500 | K18: =IF(F18<>"",H18*I18*J18,"") -> 500 | L18: =IF(K18<>"",IF(D18="INTERNO",0,K18*$L$14),"") -> 40 | M18: =IF(K18<>"",IF(E18="FAT.OGGI",SUM(K18:L18)*(1/(1-$M$14)-1),L18*(1/(1-$M$14)-1)),"") -> 9.7079657 | N18: =SUM(K18:M18) -> 549.70797 | Q18: =IF(H18<>"",H18,"") -> 1 | R18: 0 | S18: 500 | T18: =IF(Q18<>"",Q18*R18*S18,"") -> 0 | U18: =IF(Q18<>"",K18-T18,"") -> 500 | V18: =IF(Q18<>"",0%,"") -> 0 | W18: =IF(Q18<>"",V18*U18,"") -> 0 | X18: =IF(Q18<>"",W18+T18,"") -> 0 | Y18: =IF(Q18<>"",X18+M18,"") -> 9.7079657 | Z18: =IF(Q18<>"", IFERROR(U18/K18, 0), 0) -> 1 | AM18: =X18-AN18 -> 0
A19: 5 | B19: 1.1.3 | C19: ITEM | D19: OPERACIONAL | E19: FAT.CLIENTE | F19: CAFÉ EXTRA | G19: Tres corações, extra de 100 doses/dia.Insumos e descartaveis inclusos | H19: 1 | I19: 2 | J19: 850 | K19: =IF(F19<>"",H19*I19*J19,"") -> 1700 | L19: =IF(K19<>"",IF(D19="INTERNO",0,K19*$L$14),"") -> 136 | M19: =IF(K19<>"",IF(E19="FAT.OGGI",SUM(K19:L19)*(1/(1-$M$14)-1),L19*(1/(1-$M$14)-1)),"") -> 33.007083 | N19: =SUM(K19:M19) -> 1869.0071 | Q19: =IF(H19<>"",H19,"") -> 1 | R19: 1 | S19: 900 | T19: 0 | U19: =IF(Q19<>"",K19-T19,"") -> 1700 | V19: =IF(Q19<>"",0%,"") -> 0 | W19: =IF(Q19<>"",V19*U19,"") -> 0 | X19: =IF(Q19<>"",W19+T19,"") -> 0 | Y19: =IF(Q19<>"",X19+M19,"") -> 33.007083 | Z19: =IF(Q19<>"",U19/K19,"") -> 1 | AA19: =T19/#REF! -> #REF! | AM19: =X19-AN19 -> 0
A20: 6 | C20: SUBTOTAL GRUPO | F20: Subtotal EXTRAS | K20: =SUM(K17:K19) -> 5040 | L20: =SUM(L17:L19) -> 403.2 | M20: =SUM(M17:M19) -> 97.856294 | N20: =SUM(N17:N19) -> 5541.0563 | Q20: Subtotal EXTRAS | U20: =SUM(U17:U19) -> 2910 | X20: =SUM(X17:X19) -> 2130 | Y20: =IF(Q20<>"",X20+M20,"") -> 2227.8563 | Z20: Marg. Lucro | AA20: Lucro
A21: 7 | C21: SUBTOTAL PLANILHA | F21: TOTAL Mot_007_São Paulo Innovation Week 2026 | K21: =SUM(K17:K19) -> 5040 | L21: =SUM(L17:L19) -> 403.2 | M21: =SUM(M17:M19) -> 97.856294 | N21: =SUM(N17:N19) -> 5541.0563 | Q21: TOTAL | T21: =SUM(T17:T19) -> 2130 | U21: =SUM(U17:U19) -> 2910 | X21: =SUM(X17:X19) -> 2130 | Y21: =SUM(Y17:Y19) -> 2227.8563 | Z21: =IF(Q21<>"",(N21-Y21)/N21,"") -> 0.59793653 | AA21: =IF(Z21<>"",(N21-Y21),"") -> 3313.2 | AM21: =SUM(AM17:AM20) -> 0 | AN21: =SUM(AN17:AN20) -> 2130
L36: Dolby | M36: solicitar o consumo de kvas
M37: tecnico a disposição
M38: pavilhão é desligado todo dia a noite

Sheet CUSTOS OP.
F3: NOME | G3: VALOR
F4: WILLIANS GONÇALVES | G4: 281.37
F5: THIAS PONTES | G5: 290
F6: NILSON MIGUEL | G6: 521.44
F7: PATRICK BAYEUX | G7: 104.18
F8: SILVIA BRITO | G8: 558.18
F9: SILVIA BRITO | G9: 500
F10: SILVIA BRITO | G10: 450
F11: DA ORIKASSA | G11: 500
F12: ALEXANDRE WAGNER | G12: 120
F13: SK COPIADORA | G13: 150
G15: =SUM(G4:G14) -> 3475.17

Sheet Planilha1
A1: PLANILHA | B1: ITEM | C1: UNIT | D1: DIARIAS | E1: TOTAL
A2: 3.3.1 | B2: CRACHAS | C2: 30 | D2: 10 | E2: =C2*D2 -> 300
A3: 3.3.5 | B3: KVAS | C3: 350 | D3: 12 | E3: =C3*D3 -> 4200
A4: 3.3.4 | B4: TAXA DE LIMPEZA | C4: 17.5 | D4: 49 | E4: =C4*D4 -> 857.5
A5: 3.3.2 | B5: EXTINTORES | C5: 240 | D5: 2 | E5: =C5*D5 -> 480
A6: TOTAL | E6: =SUM(E2:E5) -> 5837.5

Sheet Planilha2
A1: DATA | B1: HORÁRIO | C1: ETAPA / ATIVIDADE | D1: RESPONSÁVEL PRINCIPAL | E1: EQUIPE ENVOLVIDA | F1: LOCAL | G1: STATUS
A2: 46150 | B2: 08h - 20h | C2: Início da montagem estrutural (piso elevado + rampa) | D2: Oggi Live + MV Stands | E2: Montadora + Carregadores + Prod de Montagem | F2: Arena Pacaembu
A3: 46150 | B3: 08h - 20h | C3: Entrada da equipe de cenografia | D3: Oggi Live + MV Stands | E3: Silvia + Wilson Marquezine(Prod de Montagem) | F3: Arena Pacaembu
A4: 46150 | B4: 09h - 18h | C4: Envio equipamentos Motorola para OggiLive | D4: Motorola | E4: Nilson | F4: Oggi
A5: 46151 | B5: 08h - 20h | C5: Instalação do painel de LED (3x2m) | D5: Oggi Live + Mwled | E5: Will + Montadora + Mwled | F5: Arena Pacaembu
A6: 46151 | B6: 17h | C6: Teste inicial do LED | D6: Oggi Live + Mwled | E6: Silvia supervisiona | F6: Arena Pacaembu
A7: 46152 | B7: 08h - 20h | C7: Ajustes finais da cenografia | D7: OggiLive | E7: Montadora | F7: Arena Pacaembu
A8: 46153 | B8: 08h - 20h | C8: Revisão geral do estande | D8: OggiLive | E8: Nilson + Patrick | F8: Arena Pacaembu
A9: 46154 | B9: 08h - 16h | C9: Entrada da mesa Motorola | D9: Oggi Live | E9: Carregadores | F9: Arena Pacaembu
A10: 46154 | B10: 08h - 16h | C10: Entrada do carrinho de café | D10: Oggi Live | E10: Carregadores | F10: Arena Pacaembu
A11: 46154 | B11: 08h - 16h | C11: Entrada dos equipamentos do cliente | D11: OggiLive | E11: Equipe de apoio | F11: Arena Pacaembu
A12: 46154 | B12: 08h - 16h | C12: Decoração final + abastecimento | D12: Oggi Live +Motorola | E12: Renata + Nilson | F12: Arena Pacaembu
A13: 46155 | B13: 08h - 10h | C13: Manutenção pré-evento | D13: Oggi Live | E13: Renata B. | F13: Arena Pacaembu
... A21: 46159 | B21: 13h - 20h | C21: Finalização da desmontagem | D21: OggiLive | E21: Montadora + Carregadores | F21: Arena Pacaembu
